Workbook
Name tax_rate: Assumptions!$T$40
Name acq: Assumptions!$H$8
Name year: Assumptions!$T$41
Name tgt: Assumptions!$L$8

Sheet 5-Yr Summary
A1: UrbanWind | BP1: @
A2: 5-Year Summary
B4: 44562 | C4: 44593 | D4: 44621 | E4: 44652 | F4: 44682 | G4: 44713 | H4: 44743 | I4: 44774 | J4: 44805 | K4: 44835 | L4: 44866 | M4: 44896 | N4: 2022 | O4: 44927 | P4: 44958 | Q4: 44986 | R4: 45017 | S4: 45047 | T4: 45078 | U4: 45108 | V4: 45139 | W4: 45170 | X4: 45200 | Y4: 45231 | Z4: 45261 | AA4: 2023 | AB4: 45292 | AC4: 45323 | AD4: 45352 | AE4: 45383 | AF4: 45413 | AG4: 45444 | AH4: 45474 | AI4: 45505 | AJ4: 45536 | AK4: 45566 | AL4: 45597 | AM4: 45627 | AN4: 2024 | AO4: 45658 | AP4: 45689 | AQ4: 45717 | AR4: 45748 | AS4: 45778 | AT4: 45809 | AU4: 45839 | AV4: 45870 | AW4: 45901 | AX4: 45931 | AY4: 45962 | AZ4: 45992 | BA4: 2025 | BB4: 46023 | BC4: 46054 | BD4: 46082 | BE4: 46113 | BF4: 46143 | BG4: 46174 | BH4: 46204 | BI4: 46235 | BJ4: 46266 | BK4: 46296 | BL4: 46327 | BM4: 46357 | BN4: 2026
A5: Income
A6: MMR (Services/Platform) | B6: ='Sales Forecast'!H32 -> 30 | C6: ='Sales Forecast'!I32 -> 120 | D6: ='Sales Forecast'!J32 -> 330 | E6: ='Sales Forecast'!K32 -> 615 | F6: ='Sales Forecast'!L32 -> 975 | G6: ='Sales Forecast'!M32 -> 1365 | H6: ='Sales Forecast'!N32 -> 1785 | I6: ='Sales Forecast'!O32 -> 2235 | ... M6: ='Sales Forecast'!S32 -> 4335 | N6: =SUM(B6:M6) -> 21495 | O6: ='Sales Forecast'!T32 -> 4920 | P6: ='Sales Forecast'!U32 -> 5520 | Q6: ='Sales Forecast'!V32 -> 6135 | R6: ='Sales Forecast'!W32 -> 6765 | S6: ='Sales Forecast'!X32 -> 7410 | T6: ='Sales Forecast'!Y32 -> 8085 | U6: ='Sales Forecast'!Z32 -> 8775 | V6: ='Sales Forecast'!AA32 -> 9480 | ... Z6: ='Sales Forecast'!AE32 -> 12465 | AA6: =SUM(O6:Z6) -> 102375 | AB6: ='Sales Forecast'!AF32 -> 13320 | AC6: ='Sales Forecast'!AG32 -> 14205 | AD6: ='Sales Forecast'!AH32 -> 15105 | AE6: ='Sales Forecast'!AI32 -> 16005 | AF6: ='Sales Forecast'!AJ32 -> 16905 | AG6: ='Sales Forecast'!AK32 -> 17805 | AH6: ='Sales Forecast'!AL32 -> 18705 | AI6: ='Sales Forecast'!AM32 -> 19605 | ... AM6: ='Sales Forecast'!AQ32 -> 23205 | AN6: =SUM(AB6:AM6) -> 219075 | AO6: ='Sales Forecast'!AR32 -> 24180 | AP6: ='Sales Forecast'!AS32 -> 25200 | AQ6: ='Sales Forecast'!AT32 -> 26280 | AR6: ='Sales Forecast'!AU32 -> 27420 | AS6: ='Sales Forecast'!AV32 -> 28605 | AT6: ='Sales Forecast'!AW32 -> 29790 | AU6: ='Sales Forecast'!AX32 -> 31005 | AV6: ='Sales Forecast'!AY32 -> 32220 | ... AZ6: ='Sales Forecast'!BC32 -> 37080 | BA6: =SUM(AO6:AZ6) -> 365730 | BB6: ='Sales Forecast'!BD32 -> 38340 | BC6: ='Sales Forecast'!BE32 -> 39660 | BD6: ='Sales Forecast'!BF32 -> 41010 | BE6: ='Sales Forecast'!BG32 -> 42420 | BF6: ='Sales Forecast'!BH32 -> 43875 | BG6: ='Sales Forecast'!BI32 -> 45375 | BH6: ='Sales Forecast'!BJ32 -> 46920 | BI6: ='Sales Forecast'!BK32 -> 48525 | ... BM6: ='Sales Forecast'!BO32 -> 55440 | BN6: =SUM(BB6:BM6) -> 557205
A7: Equipment Sales | B7: ='Sales Forecast'!H31 -> 40000 | C7: ='Sales Forecast'!I31 -> 230000 | D7: ='Sales Forecast'!J31 -> 480000 | E7: ='Sales Forecast'!K31 -> 620000 | F7: ='Sales Forecast'!L31 -> 820000 | G7: ='Sales Forecast'!M31 -> 840000 | H7: ='Sales Forecast'!N31 -> 860000 | I7: ='Sales Forecast'!O31 -> 880000 | ... M7: ='Sales Forecast'!S31 -> 960000 | N7: =SUM(B7:M7) -> 8490000 | O7: ='Sales Forecast'!T33 -> 0 | P7: ='Sales Forecast'!U31 -> 1050000 | Q7: ='Sales Forecast'!V31 -> 1080000 | R7: ='Sales Forecast'!W31 -> 1110000 | S7: ='Sales Forecast'!X31 -> 1140000 | T7: ='Sales Forecast'!Y31 -> 1260000 | U7: ='Sales Forecast'!Z31 -> 1290000 | V7: ='Sales Forecast'!AA31 -> 1320000 | W7: ='Sales Forecast'!AB31 -> 1350000 | ... Z7: ='Sales Forecast'!AE31 -> 1500000 | AA7: =SUM(O7:Z7) -> 13890000 | AB7: ='Sales Forecast'!AF31 -> 1700000 | AC7: ='Sales Forecast'!AG31 -> 1820000 | AD7: ='Sales Forecast'!AH31 -> 1850000 | AE7: ='Sales Forecast'!AI31 -> 1850000 | AF7: ='Sales Forecast'!AJ31 -> 1850000 | AG7: ='Sales Forecast'!AK31 -> 1850000 | AH7: ='Sales Forecast'!AL31 -> 1850000 | AI7: ='Sales Forecast'!AM31 -> 1850000 | ... AM7: ='Sales Forecast'!AQ31 -> 1850000 | AN7: =SUM(AB7:AM7) -> 22020000 | AO7: ='Sales Forecast'!AR31 -> 2050000 | AP7: ='Sales Forecast'!AS31 -> 2230000 | AQ7: ='Sales Forecast'!AT31 -> 2420000 | AR7: ='Sales Forecast'!AU31 -> 2610000 | AS7: ='Sales Forecast'!AV31 -> 2740000 | AT7: ='Sales Forecast'!AW31 -> 2740000 | AU7: ='Sales Forecast'!AX31 -> 2810000 | AV7: ='Sales Forecast'!AY31 -> 2810000 | ... AZ7: ='Sales Forecast'!BC31 -> 2810000 | BA7: =SUM(AO7:AZ7) -> 31650000 | BB7: ='Sales Forecast'!BD31 -> 2910000 | BC7: ='Sales Forecast'!BE31 -> 3100000 | BD7: ='Sales Forecast'!BF31 -> 3170000 | BE7: ='Sales Forecast'!BG31 -> 3360000 | BF7: ='Sales Forecast'!BH31 -> 3460000 | BG7: ='Sales Forecast'!BI31 -> 3620000 | BH7: ='Sales Forecast'!BJ31 -> 3720000 | BI7: ='Sales Forecast'!BK31 -> 3910000 | ... BM7: ='Sales Forecast'!BO31 -> 4610000 | BN7: =SUM(BB7:BM7) -> 44460000
A8: Channel Sales | B8: ='Sales Forecast'!H33 -> 0 | C8: ='Sales Forecast'!I33 -> 0 | D8: ='Sales Forecast'!J33 -> 0 | E8: ='Sales Forecast'!K33 -> 0 | F8: ='Sales Forecast'!L33 -> 0 | G8: ='Sales Forecast'!M33 -> 0 | H8: ='Sales Forecast'!N33 -> 0 | I8: ='Sales Forecast'!O33 -> 0 | ... M8: ='Sales Forecast'!S33 -> 0 | N8: =SUM(B8:M8) -> 0 | O8: ='Sales Forecast'!T33 -> 0 | P8: ='Sales Forecast'!U33 -> 0 | Q8: ='Sales Forecast'!V33 -> 0 | R8: ='Sales Forecast'!W33 -> 0 | S8: ='Sales Forecast'!X33 -> 0 | T8: ='Sales Forecast'!Y33 -> 0 | U8: ='Sales Forecast'!Z33 -> 0 | V8: ='Sales Forecast'!AA33 -> 0 | ... Z8: ='Sales Forecast'!AE33 -> 0 | AA8: =SUM(O8:Z8) -> 0 | AB8: ='Sales Forecast'!AF33 -> 0 | AC8: ='Sales Forecast'!AG33 -> 0 | AD8: ='Sales Forecast'!AH33 -> 0 | AE8: ='Sales Forecast'!AI33 -> 0 | AF8: ='Sales Forecast'!AJ33 -> 0 | AG8: ='Sales Forecast'!AK33 -> 0 | AH8: ='Sales Forecast'!AL33 -> 0 | AI8: ='Sales Forecast'!AM33 -> 0 | ... AM8: ='Sales Forecast'!AQ33 -> 0 | AN8: =SUM(AB8:AM8) -> 0 | AO8: ='Sales Forecast'!AR33 -> 0 | AP8: ='Sales Forecast'!AS33 -> 0 | AQ8: ='Sales Forecast'!AT33 -> 0 | AR8: ='Sales Forecast'!AU33 -> 0 | AS8: ='Sales Forecast'!AV33 -> 0 | AT8: ='Sales Forecast'!AW33 -> 0 | AU8: ='Sales Forecast'!AX33 -> 0 | AV8: ='Sales Forecast'!AY33 -> 0 | ... AZ8: ='Sales Forecast'!BC33 -> 0 | BA8: =SUM(AO8:AZ8) -> 0 | BB8: ='Sales Forecast'!BD33 -> 0 | BC8: ='Sales Forecast'!BE33 -> 0 | BD8: ='Sales Forecast'!BF33 -> 0 | BE8: ='Sales Forecast'!BG33 -> 0 | BF8: ='Sales Forecast'!BH33 -> 0 | BG8: ='Sales Forecast'!BI33 -> 0 | BH8: ='Sales Forecast'!BJ33 -> 0 | BI8: ='Sales Forecast'!BK33 -> 0 | ... BM8: ='Sales Forecast'!BO33 -> 0 | BN8: =SUM(BB8:BM8) -> 0
A9: Data and Digital Services | B9: ='Sales Forecast'!H34 -> 0 | C9: ='Sales Forecast'!I34 -> 0 | D9: ='Sales Forecast'!J34 -> 0 | E9: ='Sales Forecast'!K34 -> 0 | F9: ='Sales Forecast'!L34 -> 0 | G9: ='Sales Forecast'!M34 -> 0 | H9: ='Sales Forecast'!N34 -> 0 | I9: ='Sales Forecast'!O34 -> 0 | ... M9: ='Sales Forecast'!S34 -> 0 | N9: =SUM(B9:M9) -> 0 | O9: ='Sales Forecast'!T34 -> 0 | P9: ='Sales Forecast'!U34 -> 0 | Q9: ='Sales Forecast'!V34 -> 0 | R9: ='Sales Forecast'!W34 -> 0 | S9: ='Sales Forecast'!X34 -> 0 | T9: ='Sales Forecast'!Y34 -> 0 | U9: ='Sales Forecast'!Z34 -> 0 | V9: ='Sales Forecast'!AA34 -> 0 | ... Z9: ='Sales Forecast'!AE34 -> 0 | AA9: =SUM(O9:Z9) -> 0 | AB9: ='Sales Forecast'!AF34 -> 0 | AC9: ='Sales Forecast'!AG34 -> 0 | AD9: ='Sales Forecast'!AH34 -> 0 | AE9: ='Sales Forecast'!AI34 -> 0 | AF9: ='Sales Forecast'!AJ34 -> 0 | AG9: ='Sales Forecast'!AK34 -> 0 | AH9: ='Sales Forecast'!AL34 -> 0 | AI9: ='Sales Forecast'!AM34 -> 0 | ... AM9: ='Sales Forecast'!AQ34 -> 0 | AN9: =SUM(AB9:AM9) -> 0 | AO9: ='Sales Forecast'!AR34 -> 0 | AP9: ='Sales Forecast'!AS34 -> 0 | AQ9: ='Sales Forecast'!AT34 -> 0 | AR9: ='Sales Forecast'!AU34 -> 0 | AS9: ='Sales Forecast'!AV34 -> 0 | AT9: ='Sales Forecast'!AW34 -> 0 | AU9: ='Sales Forecast'!AX34 -> 0 | AV9: ='Sales Forecast'!AY34 -> 0 | ... AZ9: ='Sales Forecast'!BC34 -> 0 | BA9: =SUM(AO9:AZ9) -> 0 | BB9: ='Sales Forecast'!BD34 -> 0 | BC9: ='Sales Forecast'!BE34 -> 0 | BD9: ='Sales Forecast'!BF34 -> 0 | BE9: ='Sales Forecast'!BG34 -> 0 | BF9: ='Sales Forecast'!BH34 -> 0 | BG9: ='Sales Forecast'!BI34 -> 0 | BH9: ='Sales Forecast'!BJ34 -> 0 | BI9: ='Sales Forecast'!BK34 -> 0 | ... BM9: ='Sales Forecast'!BO34 -> 0 | BN9: =SUM(BB9:BM9) -> 0
N10: =SUM(B10:M10) -> 0 | O10: =SUM(C10:N10) -> 0 | P10: =SUM(D10:O10) -> 0 | Q10: =SUM(E10:P10) -> 0 | R10: =SUM(F10:Q10) -> 0 | S10: =SUM(G10:R10) -> 0 | T10: =SUM(H10:S10) -> 0 | U10: =SUM(I10:T10) -> 0 | ... BN10: =SUM(BB10:BM10) -> 0
N11: =SUM(B11:M11) -> 0 | O11: =SUM(C11:N11) -> 0 | P11: =SUM(D11:O11) -> 0 | Q11: =SUM(E11:P11) -> 0 | R11: =SUM(F11:Q11) -> 0 | S11: =SUM(G11:R11) -> 0 | T11: =SUM(H11:S11) -> 0 | U11: =SUM(I11:T11) -> 0 | ... BN11: =SUM(BB11:BM11) -> 0
N12: =SUM(B12:M12) -> 0 | O12: =SUM(C12:N12) -> 0 | P12: =SUM(D12:O12) -> 0 | Q12: =SUM(E12:P12) -> 0 | R12: =SUM(F12:Q12) -> 0 | S12: =SUM(G12:R12) -> 0 | T12: =SUM(H12:S12) -> 0 | U12: =SUM(I12:T12) -> 0 | ... BN12: =SUM(BB12:BM12) -> 0
N13: =SUM(B13:M13) -> 0 | O13: =SUM(C13:N13) -> 0 | P13: =SUM(D13:O13) -> 0 | Q13: =SUM(E13:P13) -> 0 | R13: =SUM(F13:Q13) -> 0 | S13: =SUM(G13:R13) -> 0 | T13: =SUM(H13:S13) -> 0 | U13: =SUM(I13:T13) -> 0 | ... BN13: =SUM(BB13:BM13) -> 0
N14: =+N10+N11+N12+N13 -> 0 | O14: =+O10+O11+O12+O13 -> 0 | P14: =+P10+P11+P12+P13 -> 0 | Q14: =+Q10+Q11+Q12+Q13 -> 0 | R14: =+R10+R11+R12+R13 -> 0 | S14: =+S10+S11+S12+S13 -> 0 | T14: =+T10+T11+T12+T13 -> 0 | U14: =+U10+U11+U12+U13 -> 0 | ... BN14: =+BN10+BN11+BN12+BN13 -> 0 | BO14: 50% in y 4 and 50% y5
A15: Total Sales | B15: =SUM(B7:B13) -> 40000 | C15: =SUM(C7:C13) -> 230000 | D15: =SUM(D7:D13) -> 480000 | E15: =SUM(E7:E13) -> 620000 | F15: =SUM(F7:F13) -> 820000 | G15: =SUM(G7:G13) -> 840000 | H15: =SUM(H7:H13) -> 860000 | I15: =SUM(I7:I13) -> 880000 | ... M15: =SUM(M7:M13) -> 960000 | N15: =SUM(N6:N14) -> 8511495 | O15: =SUM(O7:O13) -> 0 | P15: =SUM(P7:P13) -> 1050000 | Q15: =SUM(Q7:Q13) -> 1080000 | R15: =SUM(R7:R13) -> 1110000 | S15: =SUM(S7:S13) -> 1140000 | T15: =SUM(T7:T13) -> 1260000 | U15: =SUM(U7:U13) -> 1290000 | V15: =SUM(V7:V13) -> 1320000 | ... Z15: =SUM(Z7:Z13) -> 1500000 | AA15: =SUM(AA6:AA13) -> 13992375 | AB15: =SUM(AB7:AB13) -> 1700000 | AC15: =SUM(AC7:AC13) -> 1820000 | AD15: =SUM(AD7:AD13) -> 1850000 | AE15: =SUM(AE7:AE13) -> 1850000 | AF15: =SUM(AF7:AF13) -> 1850000 | AG15: =SUM(AG7:AG13) -> 1850000 | AH15: =SUM(AH7:AH13) -> 1850000 | AI15: =SUM(AI7:AI13) -> 1850000 | ... AM15: =SUM(AM7:AM13) -> 1850000 | AN15: =SUM(AN6:AN13) -> 22239075 | AO15: =SUM(AO7:AO13) -> 2050000 | AP15: =SUM(AP7:AP13) -> 2230000 | AQ15: =SUM(AQ7:AQ13) -> 2420000 | AR15: =SUM(AR7:AR13) -> 2610000 | AS15: =SUM(AS7:AS13) -> 2740000 | AT15: =SUM(AT7:AT13) -> 2740000 | AU15: =SUM(AU7:AU13) -> 2810000 | AV15: =SUM(AV7:AV13) -> 2810000 | ... AZ15: =SUM(AZ7:AZ13) -> 2810000 | BA15: =SUM(BA6:BA13) -> 32015730 | BB15: =SUM(BB7:BB13) -> 2910000 | BC15: =SUM(BC7:BC13) -> 3100000 | BD15: =SUM(BD7:BD13) -> 3170000 | BE15: =SUM(BE7:BE13) -> 3360000 | BF15: =SUM(BF7:BF13) -> 3460000 | BG15: =SUM(BG7:BG13) -> 3620000 | BH15: =SUM(BH7:BH13) -> 3720000 | BI15: =SUM(BI7:BI13) -> 3910000 | ... BM15: =SUM(BM7:BM13) -> 4610000 | BN15: =SUM(BN6:BN13) -> 45017205
A16: Growth | B16: n/a | C16: =IF(B15=0,"n/a",+(C15-B15)/B15) -> 4.75 | D16: =IF(C15=0,"n/a",+(D15-C15)/C15) -> 1.0869565 | E16: =IF(D15=0,"n/a",+(E15-D15)/D15) -> 0.29166667 | F16: =IF(E15=0,"n/a",+(F15-E15)/E15) -> 0.32258065 | G16: =IF(F15=0,"n/a",+(G15-F15)/F15) -> 0.024390244 | H16: =IF(G15=0,"n/a",+(H15-G15)/G15) -> 0.023809524 | I16: =IF(H15=0,"n/a",+(I15-H15)/H15) -> 0.023255814 | J16: =IF(I15=0,"n/a",+(J15-I15)/I15) -> 0.022727273 | ... M16: =IF(L15=0,"n/a",+(M15-L15)/L15) -> 0.021276596 | N16: n/a | O16: =IF(M15=0,"n/a",+(O15-M15)/M15) -> -1 | P16: =IF(O15=0,"n/a",+(P15-O15)/O15) -> n/a | Q16: =IF(P15=0,"n/a",+(Q15-P15)/P15) -> 0.028571429 | R16: =IF(Q15=0,"n/a",+(R15-Q15)/Q15) -> 0.027777778 | S16: =IF(R15=0,"n/a",+(S15-R15)/R15) -> 0.027027027 | T16: =IF(S15=0,"n/a",+(T15-S15)/S15) -> 0.10526316 | U16: =IF(T15=0,"n/a",+(U15-T15)/T15) -> 0.023809524 | V16: =IF(U15=0,"n/a",+(V15-U15)/U15) -> 0.023255814 | W16: =IF(V15=0,"n/a",+(W15-V15)/V15) -> 0.022727273 | ... Z16: =IF(Y15=0,"n/a",+(Z15-Y15)/Y15) -> 0.063829787 | AA16: =IF(N15=0,"n/a",+(AA15-N15)/N15) -> 0.64393858 | AB16: =IF(Z15=0,"n/a",+(AB15-Z15)/Z15) -> 0.13333333 | AC16: =IF(AB15=0,"n/a",+(AC15-AB15)/AB15) -> 0.070588235 | AD16: =IF(AC15=0,"n/a",+(AD15-AC15)/AC15) -> 0.016483516 | AE16: =IF(AD15=0,"n/a",+(AE15-AD15)/AD15) -> 0 | AF16: =IF(AE15=0,"n/a",+(AF15-AE15)/AE15) -> 0 | AG16: =IF(AF15=0,"n/a",+(AG15-AF15)/AF15) -> 0 | AH16: =IF(AG15=0,"n/a",+(AH15-AG15)/AG15) -> 0 | AI16: =IF(AH15=0,"n/a",+(AI15-AH15)/AH15) -> 0 | AJ16: =IF(AI15=0,"n/a",+(AJ15-AI15)/AI15) -> 0 | ... AM16: =IF(AL15=0,"n/a",+(AM15-AL15)/AL15) -> 0 | AN16: =IF(AA15=0,"n/a",+(AN15-AA15)/AA15) -> 0.589371 | AO16: =IF(AM15=0,"n/a",+(AO15-AM15)/AM15) -> 0.10810811 | AP16: =IF(AO15=0,"n/a",+(AP15-AO15)/AO15) -> 0.087804878 | AQ16: =IF(AP15=0,"n/a",+(AQ15-AP15)/AP15) -> 0.085201794 | AR16: =IF(AQ15=0,"n/a",+(AR15-AQ15)/AQ15) -> 0.078512397 | AS16: =IF(AR15=0,"n/a",+(AS15-AR15)/AR15) -> 0.049808429 | AT16: =IF(AS15=0,"n/a",+(AT15-AS15)/AS15) -> 0 | AU16: =IF(AT15=0,"n/a",+(AU15-AT15)/AT15) -> 0.025547445 | AV16: =IF(AU15=0,"n/a",+(AV15-AU15)/AU15) -> 0 | AW16: =IF(AV15=0,"n/a",+(AW15-AV15)/AV15) -> 0 | ... AZ16: =IF(AY15=0,"n/a",+(AZ15-AY15)/AY15) -> 0 | BA16: =IF(AN15=0,"n/a",+(BA15-AN15)/AN15) -> 0.43961608 | BB16: =IF(AZ15=0,"n/a",+(BB15-AZ15)/AZ15) -> 0.035587189 | BC16: =IF(BB15=0,"n/a",+(BC15-BB15)/BB15) -> 0.065292096 | BD16: =IF(BC15=0,"n/a",+(BD15-BC15)/BC15) -> 0.022580645 | BE16: =IF(BD15=0,"n/a",+(BE15-BD15)/BD15) -> 0.059936909 | BF16: =IF(BE15=0,"n/a",+(BF15-BE15)/BE15) -> 0.029761905 | BG16: =IF(BF15=0,"n/a",+(BG15-BF15)/BF15) -> 0.046242775 | BH16: =IF(BG15=0,"n/a",+(BH15-BG15)/BG15) -> 0.027624309 | BI16: =IF(BH15=0,"n/a",+(BI15-BH15)/BH15) -> 0.051075269 | BJ16: =IF(BI15=0,"n/a",+(BJ15-BI15)/BI15) -> 0.017902813 | ... BM16: =IF(BL15=0,"n/a",+(BM15-BL15)/BL15) -> 0.035955056 | BN16: =IF(BA15=0,"n/a",+(BN15-BA15)/BA15) -> 0.40609647
A17: COGS | B17: ='Monthly Income'!C8 -> 28021 | C17: ='Monthly Income'!D8 -> 161084 | D17: ='Monthly Income'!E8 -> 336231 | E17: ='Monthly Income'!F8 -> 434430.5 | F17: ='Monthly Income'!G8 -> 574682.5 | G17: ='Monthly Income'!H8 -> 588955.5 | H17: ='Monthly Income'!I8 -> 603249.5 | I17: ='Monthly Income'!J8 -> 617564.5 | ... M17: ='Monthly Income'!N8 -> 675034.5 | N17: =SUM(B17:M17) -> 5958046.5 | O17: ='Monthly Income'!O8 -> 686696.4 | P17: ='Monthly Income'!P8 -> 707198.4 | Q17: ='Monthly Income'!Q8 -> 727710.45 | R17: ='Monthly Income'!R8 -> 748232.55 | S17: ='Monthly Income'!S8 -> 768764.7 | T17: ='Monthly Income'!T8 -> 849616.95 | U17: ='Monthly Income'!U8 -> 870179.25 | V17: ='Monthly Income'!V8 -> 890751.6 | ... Z17: ='Monthly Income'!Z8 -> 1013351.6 | AA17: =SUM(O17:Z17) -> 10058291 | AB17: ='Monthly Income'!AA8 -> 1100808.1 | AC17: ='Monthly Income'!AB8 -> 1178476.7 | AD17: ='Monthly Income'!AC8 -> 1198330 | AE17: ='Monthly Income'!AD8 -> 1198908.2 | AF17: ='Monthly Income'!AE8 -> 1199486.5 | AG17: ='Monthly Income'!AF8 -> 1200064.7 | AH17: ='Monthly Income'!AG8 -> 1200643 | AI17: ='Monthly Income'!AH8 -> 1201221.2 | ... AM17: ='Monthly Income'!AL8 -> 1203534.2 | AN17: =SUM(AB17:AM17) -> 14288606 | AO17: ='Monthly Income'!AM8 -> 1327475.2 | AP17: ='Monthly Income'!AN8 -> 1443328 | AQ17: ='Monthly Income'!AO8 -> 1565619.2 | AR17: ='Monthly Income'!AP8 -> 1687948.8 | AS17: ='Monthly Income'!AQ8 -> 1771907.2 | AT17: ='Monthly Income'!AR8 -> 1772665.6 | AU17: ='Monthly Income'!AS8 -> 1818243.2 | AV17: ='Monthly Income'!AT8 -> 1819020.8 | ... AZ17: ='Monthly Income'!AX8 -> 1822131.2 | BA17: =SUM(AO17:AZ17) -> 20490067 | BB17: ='Monthly Income'!AY8 -> 1857454.2 | BC17: ='Monthly Income'!AZ8 -> 1977985.8 | BD17: ='Monthly Income'!BA8 -> 2022936.3 | BE17: ='Monthly Income'!BB8 -> 2143524.6 | BF17: ='Monthly Income'!BC8 -> 2207441.2 | BG17: ='Monthly Income'!BD8 -> 2309186.2 | BH17: ='Monthly Income'!BE8 -> 2373159.6 | BI17: ='Monthly Income'!BF8 -> 2493870.8 | ... BM17: ='Monthly Income'!BJ8 -> 2939227.2 | BN17: =SUM(BB17:BM17) -> 28360839
A18: Gross Profit | B18: =B15-B17 -> 11979 | C18: =C15-C17 -> 68916 | D18: =D15-D17 -> 143769 | E18: =E15-E17 -> 185569.5 | F18: =F15-F17 -> 245317.5 | G18: =G15-G17 -> 251044.5 | H18: =H15-H17 -> 256750.5 | I18: =I15-I17 -> 262435.5 | ... BN18: =BN15-BN17 -> 16656366
A19: Margin | B19: =IF(B15=0,"n/a",B18/B15) -> 0.299475 | C19: =IF(C15=0,"n/a",C18/C15) -> 0.29963478 | D19: =IF(D15=0,"n/a",D18/D15) -> 0.29951875 | E19: =IF(E15=0,"n/a",E18/E15) -> 0.29930565 | F19: =IF(F15=0,"n/a",F18/F15) -> 0.29916768 | G19: =IF(G15=0,"n/a",G18/G15) -> 0.2988625 | H19: =IF(H15=0,"n/a",H18/H15) -> 0.29854709 | I19: =IF(I15=0,"n/a",I18/I15) -> 0.29822216 | ... BN19: =IF(BN15=0,"n/a",BN18/BN15) -> 0.37
A20: Salary & Wages | B20: ='Monthly Income'!C12 -> 58333.333 | C20: ='Monthly Income'!D12 -> 58333.333 | D20: ='Monthly Income'!E12 -> 58333.333 | E20: ='Monthly Income'!F12 -> 73333.333 | F20: ='Monthly Income'!G12 -> 73333.333 | G20: ='Monthly Income'!H12 -> 73333.333 | H20: ='Monthly Income'!I12 -> 73333.333 | I20: ='Monthly Income'!J12 -> 87916.667 | ... M20: ='Monthly Income'!N12 -> 195000 | N20: =SUM(B20:M20) -> 1237916.7 | O20: ='Monthly Income'!O12 -> 201666.67 | P20: ='Monthly Income'!P12 -> 208333.33 | Q20: ='Monthly Income'!Q12 -> 208333.33 | R20: ='Monthly Income'!R12 -> 208333.33 | S20: ='Monthly Income'!S12 -> 208333.33 | T20: ='Monthly Income'!T12 -> 208333.33 | U20: ='Monthly Income'!U12 -> 208333.33 | V20: ='Monthly Income'!V12 -> 329166.67 | ... Z20: ='Monthly Income'!Z12 -> 361250 | AA20: =SUM(O20:Z20) -> 3178333.3 | AB20: ='Monthly Income'!AA12 -> 368750 | AC20: ='Monthly Income'!AB12 -> 368750 | AD20: ='Monthly Income'!AC12 -> 375833.33 | AE20: ='Monthly Income'!AD12 -> 382916.67 | AF20: ='Monthly Income'!AE12 -> 382916.67 | AG20: ='Monthly Income'!AF12 -> 382916.67 | AH20: ='Monthly Income'!AG12 -> 382916.67 | AI20: ='Monthly Income'!AH12 -> 382916.67 | ... AM20: ='Monthly Income'!AL12 -> 382916.67 | AN20: =SUM(AB20:AM20) -> 4559583.3 | AO20: ='Monthly Income'!AM12 -> 382916.67 | AP20: ='Monthly Income'!AN12 -> 382916.67 | AQ20: ='Monthly Income'!AO12 -> 382916.67 | AR20: ='Monthly Income'!AP12 -> 382916.67 | AS20: ='Monthly Income'!AQ12 -> 382916.67 | AT20: ='Monthly Income'!AR12 -> 382916.67 | AU20: ='Monthly Income'!AS12 -> 382916.67 | AV20: ='Monthly Income'!AT12 -> 382916.67 | ... AZ20: ='Monthly Income'!AX12 -> 382916.67 | BA20: =SUM(AO20:AZ20) -> 4595000 | BB20: ='Monthly Income'!AY12 -> 449583.33 | BC20: ='Monthly Income'!AZ12 -> 449583.33 | BD20: ='Monthly Income'!BA12 -> 449583.33 | BE20: ='Monthly Income'!BB12 -> 449583.33 | BF20: ='Monthly Income'!BC12 -> 449583.33 | BG20: ='Monthly Income'!BD12 -> 449583.33 | BH20: ='Monthly Income'!BE12 -> 449583.33 | BI20: ='Monthly Income'!BF12 -> 449583.33 | ... BM20: ='Monthly Income'!BJ12 -> 449583.33 | BN20: =SUM(BB20:BM20) -> 5395000
A21: Employee Related Expenses | B21: ='Monthly Income'!C13 -> 10354.167 | C21: ='Monthly Income'!D13 -> 10354.167 | D21: ='Monthly Income'!E13 -> 10354.167 | E21: ='Monthly Income'!F13 -> 13176.667 | F21: ='Monthly Income'!G13 -> 13176.667 | G21: ='Monthly Income'!H13 -> 13176.667 | H21: ='Monthly Income'!I13 -> 13176.667 | I21: ='Monthly Income'!J13 -> 15940.208 | ... M21: ='Monthly Income'!N13 -> 37392.5 | N21: =SUM(B21:M21) -> 229765.21 | O21: ='Monthly Income'!O13 -> 38685.833 | P21: ='Monthly Income'!P13 -> 39979.167 | Q21: ='Monthly Income'!Q13 -> 39979.167 | R21: ='Monthly Income'!R13 -> 39979.167 | S21: ='Monthly Income'!S13 -> 39979.167 | T21: ='Monthly Income'!T13 -> 39979.167 | U21: ='Monthly Income'!U13 -> 39979.167 | V21: ='Monthly Income'!V13 -> 66877.083 | ... Z21: ='Monthly Income'!Z13 -> 83316.875 | AA21: =SUM(O21:Z21) -> 661484.17 | AB21: ='Monthly Income'!AA13 -> 85078.125 | AC21: ='Monthly Income'!AB13 -> 83678.125 | AD21: ='Monthly Income'!AC13 -> 86080.417 | AE21: ='Monthly Income'!AD13 -> 87782.708 | AF21: ='Monthly Income'!AE13 -> 88482.708 | AG21: ='Monthly Income'!AF13 -> 88482.708 | AH21: ='Monthly Income'!AG13 -> 88482.708 | AI21: ='Monthly Income'!AH13 -> 88482.708 | ... AM21: ='Monthly Income'!AL13 -> 88482.708 | AN21: =SUM(AB21:AM21) -> 1050481 | AO21: ='Monthly Income'!AM13 -> 88482.708 | AP21: ='Monthly Income'!AN13 -> 88482.708 | AQ21: ='Monthly Income'!AO13 -> 88482.708 | AR21: ='Monthly Income'!AP13 -> 88482.708 | AS21: ='Monthly Income'!AQ13 -> 88482.708 | AT21: ='Monthly Income'!AR13 -> 88482.708 | AU21: ='Monthly Income'!AS13 -> 88482.708 | AV21: ='Monthly Income'!AT13 -> 88482.708 | ... AZ21: ='Monthly Income'!AX13 -> 88482.708 | BA21: =SUM(AO21:AZ21) -> 1061792.5 | BB21: ='Monthly Income'!AY13 -> 97916.042 | BC21: ='Monthly Income'!AZ13 -> 97916.042 | BD21: ='Monthly Income'!BA13 -> 97916.042 | BE21: ='Monthly Income'!BB13 -> 97916.042 | BF21: ='Monthly Income'!BC13 -> 97916.042 | BG21: ='Monthly Income'!BD13 -> 97916.042 | BH21: ='Monthly Income'!BE13 -> 97916.042 | BI21: ='Monthly Income'!BF13 -> 97916.042 | ... BM21: ='Monthly Income'!BJ13 -> 97916.042 | BN21: =SUM(BB21:BM21) -> 1174992.5
A22: Product Design & Development | B22: ='Monthly Income'!C14 -> 5300 | C22: ='Monthly Income'!D14 -> 5300 | D22: ='Monthly Income'!E14 -> 5300 | E22: ='Monthly Income'!F14 -> 5300 | F22: ='Monthly Income'!G14 -> 5300 | G22: ='Monthly Income'!H14 -> 5300 | H22: ='Monthly Income'!I14 -> 5300 | I22: ='Monthly Income'!J14 -> 5300 | ... M22: ='Monthly Income'!N14 -> 5300 | N22: =SUM(B22:M22) -> 63600 | O22: ='Monthly Income'!O14 -> 5500 | P22: ='Monthly Income'!P14 -> 5500 | Q22: ='Monthly Income'!Q14 -> 5500 | R22: ='Monthly Income'!R14 -> 5500 | S22: ='Monthly Income'!S14 -> 5500 | T22: ='Monthly Income'!T14 -> 5500 | U22: ='Monthly Income'!U14 -> 5500 | V22: ='Monthly Income'!V14 -> 5500 | ... Z22: ='Monthly Income'!Z14 -> 5500 | AA22: =SUM(O22:Z22) -> 66000 | AB22: ='Monthly Income'!AA14 -> 6050 | AC22: ='Monthly Income'!AB14 -> 6050 | AD22: ='Monthly Income'!AC14 -> 6050 | AE22: ='Monthly Income'!AD14 -> 6050 | AF22: ='Monthly Income'!AE14 -> 6050 | AG22: ='Monthly Income'!AF14 -> 6050 | AH22: ='Monthly Income'!AG14 -> 6050 | AI22: ='Monthly Income'!AH14 -> 6050 | ... AM22: ='Monthly Income'!AL14 -> 6050 | AN22: =SUM(AB22:AM22) -> 72600 | AO22: ='Monthly Income'!AM14 -> 6655 | AP22: ='Monthly Income'!AN14 -> 6655 | AQ22: ='Monthly Income'!AO14 -> 6655 | AR22: ='Monthly Income'!AP14 -> 6655 | AS22: ='Monthly Income'!AQ14 -> 6655 | AT22: ='Monthly Income'!AR14 -> 6655 | AU22: ='Monthly Income'!AS14 -> 6655 | AV22: ='Monthly Income'!AT14 -> 6655 | ... AZ22: ='Monthly Income'!AX14 -> 6655 | BA22: =SUM(AO22:AZ22) -> 79860 | BB22: ='Monthly Income'!AY14 -> 7320.5 | BC22: ='Monthly Income'!AZ14 -> 7320.5 | BD22: ='Monthly Income'!BA14 -> 7320.5 | BE22: ='Monthly Income'!BB14 -> 7320.5 | BF22: ='Monthly Income'!BC14 -> 7320.5 | BG22: ='Monthly Income'!BD14 -> 7320.5 | BH22: ='Monthly Income'!BE14 -> 7320.5 | BI22: ='Monthly Income'!BF14 -> 7320.5 | ... BM22: ='Monthly Income'!BJ14 -> 7320.5 | BN22: =SUM(BB22:BM22) -> 87846
A23: Sales & Marketing | B23: ='Monthly Income'!C15 -> 8569.0653 | C23: ='Monthly Income'!D15 -> 21875.365 | D23: ='Monthly Income'!E15 -> 39390.065 | E23: ='Monthly Income'!F15 -> 49210.015 | F23: ='Monthly Income'!G15 -> 63235.215 | G23: ='Monthly Income'!H15 -> 64662.515 | H23: ='Monthly Income'!I15 -> 66091.915 | I23: ='Monthly Income'!J15 -> 67523.415 | ... M23: ='Monthly Income'!N15 -> 73270.415 | N23: =SUM(B23:M23) -> 665008.23 | O23: ='Monthly Income'!O15 -> 77511.365 | P23: ='Monthly Income'!P15 -> 79653.365 | Q23: ='Monthly Income'!Q15 -> 81796.415 | R23: ='Monthly Income'!R15 -> 83940.515 | S23: ='Monthly Income'!S15 -> 86085.665 | T23: ='Monthly Income'!T15 -> 94532.915 | U23: ='Monthly Income'!U15 -> 96681.215 | V23: ='Monthly Income'!V15 -> 98830.565 | ... Z23: ='Monthly Income'!Z15 -> 111639.52 | AA23: =SUM(O23:Z23) -> 1120069.8 | AB23: ='Monthly Income'!AA15 -> 125699.37 | AC23: ='Monthly Income'!AB15 -> 134161.32 | AD23: ='Monthly Income'!AC15 -> 136324.32 | AE23: ='Monthly Income'!AD15 -> 136387.32 | AF23: ='Monthly Income'!AE15 -> 136450.32 | AG23: ='Monthly Income'!AF15 -> 136513.32 | AH23: ='Monthly Income'!AG15 -> 136576.32 | AI23: ='Monthly Income'!AH15 -> 136639.32 | ... AM23: ='Monthly Income'!AL15 -> 136891.32 | AN23: =SUM(AB23:AM23) -> 1625938.8 | AO23: ='Monthly Income'!AM15 -> 130217.77 | AP23: ='Monthly Income'!AN15 -> 141078.97 | AQ23: ='Monthly Income'!AO15 -> 152543.77 | AR23: ='Monthly Income'!AP15 -> 164012.17 | AS23: ='Monthly Income'!AQ15 -> 171883.27 | AT23: ='Monthly Income'!AR15 -> 171954.37 | AU23: ='Monthly Income'!AS15 -> 176227.27 | AV23: ='Monthly Income'!AT15 -> 176300.17 | ... AZ23: ='Monthly Income'!AX15 -> 176591.77 | BA23: =SUM(AO23:AZ23) -> 1990147.4 | BB23: ='Monthly Income'!AY15 -> 182667.37 | BC23: ='Monthly Income'!AZ15 -> 194146.57 | BD23: ='Monthly Income'!BA15 -> 198427.57 | BE23: ='Monthly Income'!BB15 -> 209912.17 | BF23: ='Monthly Income'!BC15 -> 215999.47 | BG23: ='Monthly Income'!BD15 -> 225689.47 | BH23: ='Monthly Income'!BE15 -> 231782.17 | BI23: ='Monthly Income'!BF15 -> 243278.47 | ... BM23: ='Monthly Income'!BJ15 -> 285693.37 | BN23: =SUM(BB23:BM23) -> 2770235.9
A24: G & A Expenses | B24: ='Monthly Income'!C16 -> 7745.9833 | C24: ='Monthly Income'!D16 -> 8696.4333 | D24: ='Monthly Income'!E16 -> 9947.4833 | E24: ='Monthly Income'!F16 -> 11823.908 | F24: ='Monthly Income'!G16 -> 12825.708 | G24: ='Monthly Income'!H16 -> 13277.658 | H24: ='Monthly Income'!I16 -> 14879.758 | I24: ='Monthly Income'!J16 -> 14657.008 | ... M24: ='Monthly Income'!N16 -> 25642.508 | N24: =SUM(B24:M24) -> 186407.48 | O24: ='Monthly Income'!O16 -> 26532.933 | P24: ='Monthly Income'!P16 -> 27273.433 | Q24: ='Monthly Income'!Q16 -> 27426.508 | R24: ='Monthly Income'!R16 -> 27579.658 | S24: ='Monthly Income'!S16 -> 27732.883 | T24: ='Monthly Income'!T16 -> 28336.258 | U24: ='Monthly Income'!U16 -> 28489.708 | V24: ='Monthly Income'!V16 -> 45093.233 | ... Z24: ='Monthly Income'!Z16 -> 65983.158 | AA24: =SUM(O24:Z24) -> 482949.38 | AB24: ='Monthly Income'!AA16 -> 68162.433 | AC24: ='Monthly Income'!AB16 -> 66416.858 | AD24: ='Monthly Income'!AC16 -> 68921.358 | AE24: ='Monthly Income'!AD16 -> 70100.858 | AF24: ='Monthly Income'!AE16 -> 71280.358 | AG24: ='Monthly Income'!AF16 -> 71284.858 | AH24: ='Monthly Income'!AG16 -> 71289.358 | AI24: ='Monthly Income'!AH16 -> 71293.858 | ... AM24: ='Monthly Income'!AL16 -> 71311.858 | AN24: =SUM(AB24:AM24) -> 843970.38 | AO24: ='Monthly Income'!AM16 -> 72316.733 | AP24: ='Monthly Income'!AN16 -> 73221.833 | AQ24: ='Monthly Income'!AO16 -> 74177.233 | AR24: ='Monthly Income'!AP16 -> 75132.933 | AS24: ='Monthly Income'!AQ16 -> 75788.858 | AT24: ='Monthly Income'!AR16 -> 75794.783 | AU24: ='Monthly Income'!AS16 -> 76150.858 | AV24: ='Monthly Income'!AT16 -> 76156.933 | ... AZ24: ='Monthly Income'!AX16 -> 76181.233 | BA24: =SUM(AO24:AZ24) -> 903428.65 | BB24: ='Monthly Income'!AY16 -> 76687.533 | BC24: ='Monthly Income'!AZ16 -> 77644.133 | BD24: ='Monthly Income'!BA16 -> 78000.883 | BE24: ='Monthly Income'!BB16 -> 78957.933 | BF24: ='Monthly Income'!BC16 -> 79465.208 | BG24: ='Monthly Income'!BD16 -> 80272.708 | BH24: ='Monthly Income'!BE16 -> 80780.433 | BI24: ='Monthly Income'!BF16 -> 81738.458 | ... BM24: ='Monthly Income'!BJ16 -> 85273.033 | BN24: =SUM(BB24:BM24) -> 968436.03
A25: Total Operating Expenses | B25: =SUM(B20:B24) -> 90302.549 | C25: =SUM(C20:C24) -> 104559.3 | D25: =SUM(D20:D24) -> 123325.05 | E25: =SUM(E20:E24) -> 152843.92 | F25: =SUM(F20:F24) -> 167870.92 | G25: =SUM(G20:G24) -> 169750.17 | H25: =SUM(H20:H24) -> 172781.67 | I25: =SUM(I20:I24) -> 191337.3 | ... BN25: =SUM(BN20:BN24) -> 10396510
A27: % of sales | B27: =IF(B15=0,"n/a",B25/B15) -> 2.2575637 | C27: =IF(C15=0,"n/a",C25/C15) -> 0.45460565 | D27: =IF(D15=0,"n/a",D25/D15) -> 0.25692718 | E27: =IF(E15=0,"n/a",E25/E15) -> 0.24652246 | F27: =IF(F15=0,"n/a",F25/F15) -> 0.20472064 | G27: =IF(G15=0,"n/a",G25/G15) -> 0.20208354 | H27: =IF(H15=0,"n/a",H25/H15) -> 0.20090892 | I27: =IF(I15=0,"n/a",I25/I15) -> 0.21742875 | ... BN27: =IF(BN15=0,"n/a",BN25/BN15) -> 0.23094527
A28: EBITDA | B28: =B18-B25 -> -78323.549 | C28: =C18-C25 -> -35643.299 | D28: =D18-D25 -> 20443.951 | E28: =E18-E25 -> 32725.576 | F28: =F18-F25 -> 77446.576 | G28: =G18-G25 -> 81294.326 | H28: =H18-H25 -> 83968.826 | I28: =I18-I25 -> 71098.201 | ... BN28: =BN18-BN25 -> 6259855.4
A29: % of sales | B29: =IF(B15=0,"n/a",B28/B15) -> -1.9580887 | C29: =IF(C15=0,"n/a",C28/C15) -> -0.15497086 | D29: =IF(D15=0,"n/a",D28/D15) -> 0.042591565 | E29: =IF(E15=0,"n/a",E28/E15) -> 0.052783188 | F29: =IF(F15=0,"n/a",F28/F15) -> 0.094447044 | G29: =IF(G15=0,"n/a",G28/G15) -> 0.09677896 | H29: =IF(H15=0,"n/a",H28/H15) -> 0.09763817 | I29: =IF(I15=0,"n/a",I28/I15) -> 0.080793411 | ... BN29: =IF(BN15=0,"n/a",BN28/BN15) -> 0.13905473
A30: EBIT | B30: ='Monthly Income'!C24 -> -78343.549 | C30: ='Monthly Income'!D24 -> -35573.299 | D30: ='Monthly Income'!E24 -> 20723.951 | E30: ='Monthly Income'!F24 -> 33273.91 | F30: ='Monthly Income'!G24 -> 78354.91 | G30: ='Monthly Income'!H24 -> 82592.66 | H30: ='Monthly Income'!I24 -> 85687.16 | I30: ='Monthly Income'!J24 -> 73249.868 | ... M30: ='Monthly Income'!N24 -> -47538.257 | N30: =SUM(B30:M30) -> 169450.92 | O30: ='Monthly Income'!O24 -> -11914.865 | P30: ='Monthly Income'!P24 -> -12667.699 | Q30: ='Monthly Income'!Q24 -> -4860.8736 | R30: ='Monthly Income'!R24 -> 2949.7764 | S30: ='Monthly Income'!S24 -> 10764.251 | T30: ='Monthly Income'!T24 -> 41536.376 | U30: ='Monthly Income'!U24 -> 49362.326 | V30: ='Monthly Income'!V24 -> -107222.48 | ... Z30: ='Monthly Income'!Z24 -> -129342.77 | AA30: =SUM(O30:Z30) -> -559794.62 | AB30: ='Monthly Income'!AA24 -> -42011.357 | AC30: ='Monthly Income'!AB24 -> -4078.0111 | AD30: ='Monthly Income'!AC24 -> -7217.7194 | AE30: ='Monthly Income'!AD24 -> -16940.761 | AF30: ='Monthly Income'!AE24 -> -18578.178 | AG30: ='Monthly Income'!AF24 -> -18323.928 | AH30: ='Monthly Income'!AG24 -> -18069.678 | AI30: ='Monthly Income'!AH24 -> -17815.428 | ... AM30: ='Monthly Income'!AL24 -> -16798.428 | AN30: =SUM(AB30:AM30) -> -211754.27 | AO30: ='Monthly Income'!AM24 -> 65299.26 | AP30: ='Monthly Income'!AN24 -> 118700.16 | AQ30: ='Monthly Income'!AO24 -> 175068.76 | AR30: ='Monthly Income'!AP24 -> 231455.06 | AS30: ='Monthly Income'!AQ24 -> 270154.63 | AT30: ='Monthly Income'!AR24 -> 270504.21 | AU30: ='Monthly Income'!AS24 -> 291512.63 | AV30: ='Monthly Income'!AT24 -> 291871.06 | ... AZ30: ='Monthly Income'!AX24 -> 293304.76 | BA30: =SUM(AO30:AZ30) -> 2885634.3 | BB30: ='Monthly Income'!AY24 -> 275894.36 | BC30: ='Monthly Income'!AZ24 -> 334246.96 | BD30: ='Monthly Income'!BA24 -> 356008.71 | BE30: ='Monthly Income'!BB24 -> 414388.76 | BF30: ='Monthly Income'!BC24 -> 445332.53 | BG30: ='Monthly Income'!BD24 -> 494590.03 | BH30: ='Monthly Income'!BE24 -> 525561.26 | BI30: ='Monthly Income'!BF24 -> 584000.78 | ... BM30: ='Monthly Income'!BJ24 -> 799609.86 | BN30: =SUM(BB30:BM30) -> 6250055.4
A31: % of sales | B31: =IF(B15=0,"n/a",B30/B15) -> -1.9585887 | C31: =IF(C15=0,"n/a",C30/C15) -> -0.15466652 | D31: =IF(D15=0,"n/a",D30/D15) -> 0.043174899 | E31: =IF(E15=0,"n/a",E30/E15) -> 0.053667596 | F31: =IF(F15=0,"n/a",F30/F15) -> 0.095554768 | G31: =IF(G15=0,"n/a",G30/G15) -> 0.098324595 | H31: =IF(H15=0,"n/a",H30/H15) -> 0.099636232 | I31: =IF(I15=0,"n/a",I30/I15) -> 0.083238486 | ... BN31: =IF(BN15=0,"n/a",BN30/BN15) -> 0.13883704
A32: NI | B32: ='Monthly Income'!C28 -> -51706.742 | C32: ='Monthly Income'!D28 -> -23478.377 | D32: ='Monthly Income'!E28 -> 13677.808 | E32: ='Monthly Income'!F28 -> 21960.78 | F32: ='Monthly Income'!G28 -> 51714.24 | G32: ='Monthly Income'!H28 -> 54511.155 | H32: ='Monthly Income'!I28 -> 56553.525 | I32: ='Monthly Income'!J28 -> 48344.913 | ... M32: ='Monthly Income'!N28 -> -31375.25 | N32: =SUM(B32:M32) -> 111837.61 | O32: ='Monthly Income'!O28 -> -7863.8111 | P32: ='Monthly Income'!P28 -> -8360.6811 | Q32: ='Monthly Income'!Q28 -> -3208.1766 | R32: ='Monthly Income'!R28 -> 1946.8524 | S32: ='Monthly Income'!S28 -> 7104.4059 | T32: ='Monthly Income'!T28 -> 27414.008 | U32: ='Monthly Income'!U28 -> 32579.135 | V32: ='Monthly Income'!V28 -> -70766.838 | ... Z32: ='Monthly Income'!Z28 -> -85366.225 | AA32: =SUM(O32:Z32) -> -369464.45 | AB32: ='Monthly Income'!AA28 -> -27727.496 | AC32: ='Monthly Income'!AB28 -> -2691.4873 | AD32: ='Monthly Income'!AC28 -> -4763.6948 | AE32: ='Monthly Income'!AD28 -> -11180.902 | AF32: ='Monthly Income'!AE28 -> -12261.597 | AG32: ='Monthly Income'!AF28 -> -12093.792 | AH32: ='Monthly Income'!AG28 -> -11925.987 | AI32: ='Monthly Income'!AH28 -> -11758.182 | ... AM32: ='Monthly Income'!AL28 -> -11086.962 | AN32: =SUM(AB32:AM32) -> -139757.82 | AO32: ='Monthly Income'!AM28 -> 43097.511 | AP32: ='Monthly Income'!AN28 -> 78342.105 | AQ32: ='Monthly Income'!AO28 -> 115545.38 | AR32: ='Monthly Income'!AP28 -> 152760.34 | AS32: ='Monthly Income'!AQ28 -> 178302.06 | AT32: ='Monthly Income'!AR28 -> 178532.78 | AU32: ='Monthly Income'!AS28 -> 192398.34 | AV32: ='Monthly Income'!AT28 -> 192634.9 | ... AZ32: ='Monthly Income'!AX28 -> 193581.14 | BA32: =SUM(AO32:AZ32) -> 1904518.6 | BB32: ='Monthly Income'!AY28 -> 182090.28 | BC32: ='Monthly Income'!AZ28 -> 220602.99 | BD32: ='Monthly Income'!BA28 -> 234965.75 | BE32: ='Monthly Income'!BB28 -> 273496.58 | BF32: ='Monthly Income'!BC28 -> 293919.47 | BG32: ='Monthly Income'!BD28 -> 326429.42 | BH32: ='Monthly Income'!BE28 -> 346870.43 | BI32: ='Monthly Income'!BF28 -> 385440.52 | ... BM32: ='Monthly Income'!BJ28 -> 527742.51 | BN32: =SUM(BB32:BM32) -> 4125036.6
A33: % of sales | B33: =IF(B15=0,"n/a",B32/B15) -> -1.2926686 | C33: =IF(C15=0,"n/a",C32/C15) -> -0.1020799 | D33: =IF(D15=0,"n/a",D32/D15) -> 0.028495433 | E33: =IF(E15=0,"n/a",E32/E15) -> 0.035420614 | F33: =IF(F15=0,"n/a",F32/F15) -> 0.063066147 | G33: =IF(G15=0,"n/a",G32/G15) -> 0.064894233 | H33: =IF(H15=0,"n/a",H32/H15) -> 0.065759913 | I33: =IF(I15=0,"n/a",I32/I15) -> 0.054937401 | ... BN33: =IF(BN15=0,"n/a",BN32/BN15) -> 0.091632446
A34: Cash
A35: Cash, Beginning Balance | B35: =Cashflow!G24 -> 155313.26 | C35: =Cashflow!H24 -> 155313.26 | D35: =Cashflow!I24 -> 220308.38 | E35: =Cashflow!J24 -> 242844.19 | F35: =Cashflow!K24 -> 107097.89 | G35: =Cashflow!L24 -> 217530.04 | H35: =Cashflow!M24 -> 224722.37 | I35: =Cashflow!N24 -> 260927.06 | ... M35: =Cashflow!R24 -> 190595.52 | N35: =B35 -> 155313.26 | O35: =Cashflow!S24 -> 137888.11 | P35: =Cashflow!T24 -> 90557.011 | Q35: =Cashflow!U24 -> 31933.78 | R35: =Cashflow!V24 -> 9998363.1 | S35: =Cashflow!W24 -> 9969932.4 | T35: =Cashflow!X24 -> 9946644.3 | U35: =Cashflow!Y24 -> 9868488.2 | V35: =Cashflow!Z24 -> 9855779.9 | ... Z35: =Cashflow!AD24 -> 9373703.1 | AA35: =N38 -> 293201.36 | AB35: =Cashflow!AE24 -> 9205228.5 | AC35: =Cashflow!AF24 -> 9018149.9 | AD35: =Cashflow!AG24 -> 8862232.4 | AE35: =Cashflow!AH24 -> 8809267.2 | AF35: =Cashflow!AI24 -> 8791623.8 | AG35: =Cashflow!AJ24 -> 8778278.9 | AH35: =Cashflow!AK24 -> 8766101.7 | AI35: =Cashflow!AL24 -> 8754092.4 | ... AM35: =Cashflow!AP24 -> 8707733.2 | AN35: =AA38 -> 9360541.8 | AO35: =Cashflow!AQ24 -> 8696562.9 | AP35: =Cashflow!AR24 -> 8577858.2 | AQ35: =Cashflow!AS24 -> 8470063.6 | AR35: =Cashflow!AT24 -> 8397156.4 | AS35: =Cashflow!AU24 -> 8359604.2 | AT35: =Cashflow!AV24 -> 8396746 | AU35: =Cashflow!AW24 -> 8551510.5 | AV35: =Cashflow!AX24 -> 8686115.9 | ... AZ35: =Cashflow!BB24 -> 9443881.5 | BA35: =AN38 -> 8851876.1 | BB35: =Cashflow!BC24 -> 9637064.3 | BC35: =Cashflow!BD24 -> 9751461.1 | BD35: =Cashflow!BE24 -> 9783986.4 | BE35: =Cashflow!BF24 -> 9926224.4 | BF35: =Cashflow!BG24 -> 10031339 | BG35: =Cashflow!BH24 -> 10207978 | BH35: =Cashflow!BI24 -> 10384833 | BI35: =Cashflow!BJ24 -> 10619883 | ... BM35: =Cashflow!BN24 -> 11638705 | BN35: =BA38 -> 9792377.6
A36: Change in Cash from Operations | B36: =Cashflow!G27 -> -94686.742 | C36: =Cashflow!H27 -> -185004.88 | D36: =Cashflow!I27 -> -227464.19 | E36: =Cashflow!J27 -> -135746.3 | F36: =Cashflow!K27 -> -139567.84 | G36: =Cashflow!L27 -> 7192.3221 | H36: =Cashflow!M27 -> 36204.692 | I36: =Cashflow!N27 -> 26982.746 | ... M36: =Cashflow!R27 -> -52707.416 | N36: =SUM(B36:M36) -> -862111.89 | O36: =Cashflow!S27 -> -47331.094 | P36: =Cashflow!T27 -> -58623.231 | Q36: =Cashflow!U27 -> -33570.702 | R36: =Cashflow!V27 -> -28430.673 | S36: =Cashflow!W27 -> -23288.119 | T36: =Cashflow!X27 -> -78156.042 | U36: =Cashflow!Y27 -> -12708.39 | V36: =Cashflow!Z27 -> -114986.03 | ... Z36: =Cashflow!AD27 -> -168474.61 | AA36: =SUM(O36:Z36) -> -932659.59 | AB36: =Cashflow!AE27 -> -187078.64 | AC36: =Cashflow!AF27 -> -155917.52 | AD36: =Cashflow!AG27 -> -52965.18 | AE36: =Cashflow!AH27 -> -17643.402 | AF36: =Cashflow!AI27 -> -13344.931 | AG36: =Cashflow!AJ27 -> -12177.126 | AH36: =Cashflow!AK27 -> -12009.321 | AI36: =Cashflow!AL27 -> -11841.516 | ... AM36: =Cashflow!AP27 -> -11170.296 | AN36: =SUM(AB36:AM36) -> -508665.64 | AO36: =Cashflow!AQ27 -> -118704.69 | AP36: =Cashflow!AR27 -> -107794.63 | AQ36: =Cashflow!AS27 -> -72907.152 | AR36: =Cashflow!AT27 -> -37552.194 | AS36: =Cashflow!AU27 -> 37141.826 | AT36: =Cashflow!AV27 -> 154764.45 | AU36: =Cashflow!AW27 -> 134605.41 | AV36: =Cashflow!AX27 -> 179636.57 | ... AZ36: =Cashflow!BB27 -> 193182.81 | BA36: =SUM(AO36:AZ36) -> 940501.44 | BB36: =Cashflow!BC27 -> 114396.74 | BC36: =Cashflow!BD27 -> 32525.36 | BD36: =Cashflow!BE27 -> 142237.97 | BE36: =Cashflow!BF27 -> 105114.35 | BF36: =Cashflow!BG27 -> 176639.46 | BG36: =Cashflow!BH27 -> 176854.41 | BH36: =Cashflow!BI27 -> 235050.42 | BI36: =Cashflow!BJ27 -> 211313.28 | ... BM36: =Cashflow!BN27 -> 344552.5 | BN36: =SUM(BB36:BM36) -> 2346193.7
A37: Change in Cash from Financing | B37: =Cashflow!G20 -> 250000 | C37: =Cashflow!H20 -> 250000 | D37: =Cashflow!I20 -> 250000 | E37: =Cashflow!J20 -> 0 | F37: =Cashflow!K20 -> 250000 | G37: =Cashflow!L20 -> 0 | H37: =Cashflow!M20 -> 0 | I37: =Cashflow!N20 -> 0 | ... M37: =Cashflow!R20 -> 0 | N37: =SUM(B37:M37) -> 1000000 | O37: =Cashflow!S20 -> 0 | P37: =Cashflow!T20 -> 0 | Q37: =Cashflow!U20 -> 10000000 | R37: =Cashflow!V20 -> 0 | S37: =Cashflow!W20 -> 0 | T37: =Cashflow!X20 -> 0 | U37: =Cashflow!Y20 -> 0 | V37: =Cashflow!Z20 -> 0 | ... Z37: =Cashflow!AD20 -> 0 | AA37: =SUM(O37:Z37) -> 10000000 | AB37: =Cashflow!AE20 -> 0 | AC37: =Cashflow!AF20 -> 0 | AD37: =Cashflow!AG20 -> 0 | AE37: =Cashflow!AH20 -> 0 | AF37: =Cashflow!AI20 -> 0 | AG37: =Cashflow!AJ20 -> 0 | AH37: =Cashflow!AK20 -> 0 | AI37: =Cashflow!AL20 -> 0 | ... AM37: =Cashflow!AP20 -> 0 | AN37: =SUM(AB37:AM37) -> 0 | AO37: =Cashflow!AQ20 -> 0 | AP37: =Cashflow!AR20 -> 0 | AQ37: =Cashflow!AS20 -> 0 | AR37: =Cashflow!AT20 -> 0 | AS37: =Cashflow!AU20 -> 0 | AT37: =Cashflow!AV20 -> 0 | AU37: =Cashflow!AW20 -> 0 | AV37: =Cashflow!AX20 -> 0 | ... AZ37: =Cashflow!BB20 -> 0 | BA37: =SUM(AO37:AZ37) -> 0 | BB37: =Cashflow!BC20 -> 0 | BC37: =Cashflow!BD20 -> 0 | BD37: =Cashflow!BE20 -> 0 | BE37: =Cashflow!BF20 -> 0 | BF37: =Cashflow!BG20 -> 0 | BG37: =Cashflow!BH20 -> 0 | BH37: =Cashflow!BI20 -> 0 | BI37: =Cashflow!BJ20 -> 0 | ... BM37: =Cashflow!BN20 -> 0 | BN37: =SUM(BB37:BM37) -> 0
A38: Cash, Ending Balance | B38: =SUM(B35:B37) -> 310626.52 | C38: =SUM(C35:C37) -> 220308.38 | D38: =SUM(D35:D37) -> 242844.19 | E38: =SUM(E35:E37) -> 107097.89 | F38: =SUM(F35:F37) -> 217530.04 | G38: =SUM(G35:G37) -> 224722.37 | H38: =SUM(H35:H37) -> 260927.06 | I38: =SUM(I35:I37) -> 287909.8 | ... BN38: =SUM(BN35:BN37) -> 12138571
A39: Headcount
A40: FTE & Contract | B40: ='People Costs'!H20+Contractors!H20 -> 5.25 | C40: ='People Costs'!I20+Contractors!I20 -> 8.25 | D40: ='People Costs'!J20+Contractors!J20 -> 8.25 | E40: ='People Costs'!K20+Contractors!K20 -> 11.5 | F40: ='People Costs'!L20+Contractors!L20 -> 13.5 | G40: ='People Costs'!M20+Contractors!M20 -> 17 | H40: ='People Costs'!N20+Contractors!N20 -> 4 | I40: ='People Costs'!O20+Contractors!O20 -> 5 | ... M40: ='People Costs'!S20+Contractors!S20 -> 14 | N40: =M40 -> 14 | O40: ='People Costs'!T20+Contractors!T20 -> 14.5 | P40: ='People Costs'!U20 -> 15 | Q40: ='People Costs'!V20 -> 15 | R40: ='People Costs'!W20 -> 15 | S40: ='People Costs'!X20 -> 15 | T40: ='People Costs'!Y20 -> 15 | U40: ='People Costs'!Z20 -> 15 | V40: ='People Costs'!AA20 -> 29 | W40: ='People Costs'!AB20 -> 39 | ... Z40: ='People Costs'!AE20 -> 46 | AA40: =Z40 -> 46 | AB40: ='People Costs'!AF20+Contractors!AF20 -> 47 | AC40: ='People Costs'!AG20+Contractors!AG20 -> 45 | AD40: ='People Costs'!AH20+Contractors!AH20 -> 47 | AE40: ='People Costs'!AI20+Contractors!AI20 -> 48 | AF40: ='People Costs'!AJ20+Contractors!AJ20 -> 49 | AG40: ='People Costs'!AK20+Contractors!AK20 -> 49 | AH40: ='People Costs'!AL20+Contractors!AL20 -> 49 | AI40: ='People Costs'!AM20+Contractors!AM20 -> 49 | ... AM40: ='People Costs'!AQ20+Contractors!AQ20 -> 49 | AN40: =AM40 -> 49 | AO40: ='People Costs'!AR20+Contractors!AR20 -> 49 | AP40: ='People Costs'!AS20+Contractors!AS20 -> 49 | AQ40: ='People Costs'!AT20+Contractors!AT20 -> 49 | AR40: ='People Costs'!AU20+Contractors!AU20 -> 49 | AS40: ='People Costs'!AV20+Contractors!AV20 -> 49 | AT40: ='People Costs'!AW20+Contractors!AW20 -> 49 | AU40: ='People Costs'!AX20+Contractors!AX20 -> 49 | AV40: ='People Costs'!AY20+Contractors!AY20 -> 49 | ... AZ40: ='People Costs'!BC20+Contractors!BC20 -> 49 | BA40: =AZ40 -> 49 | BB40: ='People Costs'!BD20+Contractors!BD20 -> 49 | BC40: ='People Costs'!BE20+Contractors!BE20 -> 49 | BD40: ='People Costs'!BF20+Contractors!BF20 -> 49 | BE40: ='People Costs'!BG20+Contractors!BG20 -> 49 | BF40: ='People Costs'!BH20+Contractors!BH20 -> 49 | BG40: ='People Costs'!BI20+Contractors!BI20 -> 49 | BH40: ='People Costs'!BJ20+Contractors!BJ20 -> 49 | BI40: ='People Costs'!BK20+Contractors!BK20 -> 49 | ... BM40: ='People Costs'!BO20+Contractors!BO20 -> 49 | BN40: =BM40 -> 49
A42: Rev Per FTE | N42: =+N15/N40 -> 607963.93 | O42: =+O15/O40 -> 0 | P42: =+P15/P40 -> 70000 | Q42: =+Q15/Q40 -> 72000 | R42: =+R15/R40 -> 74000 | S42: =+S15/S40 -> 76000 | T42: =+T15/T40 -> 84000 | U42: =+U15/U40 -> 86000 | ... BN42: =+BN15/BN40 -> 918718.47
A43: Marketing % of Rev | N43: =N23/N15 -> 0.078130603 | O43: =O23/O15 -> #DIV/0! | P43: =P23/P15 -> 0.075860348 | Q43: =Q23/Q15 -> 0.075737422 | R43: =R23/R15 -> 0.075622086 | S43: =S23/S15 -> 0.075513741 | T43: =T23/T15 -> 0.075026123 | U43: =U23/U15 -> 0.074946678 | ... BN43: =BN23/BN15 -> 0.06153727
...

Sheet Graphs
B5: Year 1 | C5: Year 2 | D5: Year 3 | E5: Year 4 | F5: Year 5
A6: Total Sales | B6: ='5-Yr Summary'!N15 -> 8511495 | C6: ='5-Yr Summary'!AA15 -> 13992375 | D6: ='5-Yr Summary'!AN15 -> 22239075 | E6: ='5-Yr Summary'!BA15 -> 32015730 | F6: ='5-Yr Summary'!BN15 -> 45017205
A7: Gross Profit | B7: ='5-Yr Summary'!N18 -> 2553448.5 | C7: =+'5-Yr Summary'!AA18 -> 3934083.8 | D7: =+'5-Yr Summary'!AN18 -> 7950469.3 | E7: =+'5-Yr Summary'!BA18 -> 11525663 | F7: =+'5-Yr Summary'!BN18 -> 16656366
A8: Total Operating Expenses | B8: =+'5-Yr Summary'!N25 -> 2382697.6 | C8: =+'5-Yr Summary'!AA25 -> 5508836.7 | D8: =+'5-Yr Summary'!AN25 -> 8152573.6 | E8: =+'5-Yr Summary'!BA25 -> 8630228.5 | F8: =+'5-Yr Summary'!BN25 -> 10396510
A9: EBITDA | B9: =+'5-Yr Summary'!N28 -> 170750.92 | C9: =+'5-Yr Summary'!AA28 -> -1574753 | D9: =+'5-Yr Summary'!AN28 -> -202104.27 | E9: =+'5-Yr Summary'!BA28 -> 2895434.3 | F9: =+'5-Yr Summary'!BN28 -> 6259855.4
A22: Total Sales | B22: =+B6 -> 8511495 | C22: =+C6 -> 13992375 | D22: =+D6 -> 22239075 | E22: =+E6 -> 32015730 | F22: =+F6 -> 45017205
A23: EBITDA | B23: =+B9 -> 170750.92 | C23: =+C9 -> -1574753 | D23: =+D9 -> -202104.27 | E23: =+E9 -> 2895434.3 | F23: =+F9 -> 6259855.4

Sheet Monthly Income
A1: UrbanWind
A2: Monthly Income Statements
C5: 44562 | D5: 44593 | E5: 44621 | F5: 44652 | G5: 44682 | H5: 44713 | I5: 44743 | J5: 44774 | K5: 44805 | L5: 44835 | M5: 44866 | N5: 44896 | O5: 44927 | P5: 44958 | Q5: 44986 | R5: 45017 | S5: 45047 | T5: 45078 | U5: 45108 | V5: 45139 | W5: 45170 | X5: 45200 | Y5: 45231 | Z5: 45261 | AA5: 45292 | AB5: 45323 | AC5: 45352 | AD5: 45383 | AE5: 45413 | AF5: 45444 | AG5: 45474 | AH5: 45505 | AI5: 45536 | AJ5: 45566 | AK5: 45597 | AL5: 45627 | AM5: 45658 | AN5: 45689 | AO5: 45717 | AP5: 45748 | AQ5: 45778 | AR5: 45809 | AS5: 45839 | AT5: 45870 | AU5: 45901 | AV5: 45931 | AW5: 45962 | AX5: 45992 | AY5: 46023 | AZ5: 46054 | BA5: 46082 | BB5: 46113 | BC5: 46143 | BD5: 46174 | BE5: 46204 | BF5: 46235 | BG5: 46266 | BH5: 46296 | BI5: 46327 | BJ5: 46357
A7: Sales | C7: ='Sales Forecast'!H37 -> 40030 | D7: ='Sales Forecast'!I37 -> 230120 | E7: ='Sales Forecast'!J37 -> 480330 | F7: ='Sales Forecast'!K37 -> 620615 | G7: ='Sales Forecast'!L37 -> 820975 | H7: ='Sales Forecast'!M37 -> 841365 | I7: ='Sales Forecast'!N37 -> 861785 | J7: ='Sales Forecast'!O37 -> 882235 | ... BJ7: ='Sales Forecast'!BO37 -> 4665440
A8: Cost of Goods Sold | C8: =COGS!G14 -> 28021 | D8: =COGS!H14 -> 161084 | E8: =COGS!I14 -> 336231 | F8: =COGS!J14 -> 434430.5 | G8: =COGS!K14 -> 574682.5 | H8: =COGS!L14 -> 588955.5 | I8: =COGS!M14 -> 603249.5 | J8: =COGS!N14 -> 617564.5 | ... BJ8: =COGS!BN14 -> 2939227.2
A9: Gross Profit | C9: =C7-C8 -> 12009 | D9: =D7-D8 -> 69036 | E9: =E7-E8 -> 144099 | F9: =F7-F8 -> 186184.5 | G9: =G7-G8 -> 246292.5 | H9: =H7-H8 -> 252409.5 | I9: =I7-I8 -> 258535.5 | J9: =J7-J8 -> 264670.5 | ... BJ9: =BJ7-BJ8 -> 1726212.8
A10: Gross Margin | C10: =+IF(C9>0,C9/C7,"n/a") -> 0.3 | D10: =+IF(D9>0,D9/D7,"n/a") -> 0.3 | E10: =+IF(E9>0,E9/E7,"n/a") -> 0.3 | F10: =+IF(F9>0,F9/F7,"n/a") -> 0.3 | G10: =+IF(G9>0,G9/G7,"n/a") -> 0.3 | H10: =+IF(H9>0,H9/H7,"n/a") -> 0.3 | I10: =+IF(I9>0,I9/I7,"n/a") -> 0.3 | J10: =+IF(J9>0,J9/J7,"n/a") -> 0.3 | ... BJ10: =+IF(BJ9>0,BJ9/BJ7,"n/a") -> 0.37
A11: Operating Expenses
A12: Salary & Wages | C12: ='People Costs'!H13 -> 58333.333 | D12: ='People Costs'!I13 -> 58333.333 | E12: ='People Costs'!J13 -> 58333.333 | F12: ='People Costs'!K13 -> 73333.333 | G12: ='People Costs'!L13 -> 73333.333 | H12: ='People Costs'!M13 -> 73333.333 | I12: ='People Costs'!N13 -> 73333.333 | J12: ='People Costs'!O13 -> 87916.667 | ... BJ12: ='People Costs'!BO13 -> 449583.33
A13: Employee Related Expenses | C13: ='People Costs'!H17 -> 10354.167 | D13: ='People Costs'!I17 -> 10354.167 | E13: ='People Costs'!J17 -> 10354.167 | F13: ='People Costs'!K17 -> 13176.667 | G13: ='People Costs'!L17 -> 13176.667 | H13: ='People Costs'!M17 -> 13176.667 | I13: ='People Costs'!N17 -> 13176.667 | J13: ='People Costs'!O17 -> 15940.208 | ... BJ13: ='People Costs'!BO17 -> 97916.042
A14: Product Design & Development | C14: =OpEx!G18 -> 5300 | D14: =OpEx!H18 -> 5300 | E14: =OpEx!I18 -> 5300 | F14: =OpEx!J18 -> 5300 | G14: =OpEx!K18 -> 5300 | H14: =OpEx!L18 -> 5300 | I14: =OpEx!M18 -> 5300 | J14: =OpEx!N18 -> 5300 | ... BJ14: =OpEx!BN18 -> 7320.5
A15: Sales & Marketing | C15: =OpEx!G27 -> 8569.0653 | D15: =OpEx!H27 -> 21875.365 | E15: =OpEx!I27 -> 39390.065 | F15: =OpEx!J27 -> 49210.015 | G15: =OpEx!K27 -> 63235.215 | H15: =OpEx!L27 -> 64662.515 | I15: =OpEx!M27 -> 66091.915 | J15: =OpEx!N27 -> 67523.415 | ... BJ15: =OpEx!BN27 -> 285693.37
A16: G & A Expenses | C16: =OpEx!G46 -> 7745.9833 | D16: =OpEx!H46 -> 8696.4333 | E16: =OpEx!I46 -> 9947.4833 | F16: =OpEx!J46 -> 11823.908 | G16: =OpEx!K46 -> 12825.708 | H16: =OpEx!L46 -> 13277.658 | I16: =OpEx!M46 -> 14879.758 | J16: =OpEx!N46 -> 14657.008 | ... BJ16: =OpEx!BN46 -> 85273.033
A17: Total Operating Expenses | C17: =SUM(C12:C16) -> 90302.549 | D17: =SUM(D12:D16) -> 104559.3 | E17: =SUM(E12:E16) -> 123325.05 | F17: =SUM(F12:F16) -> 152843.92 | G17: =SUM(G12:G16) -> 167870.92 | H17: =SUM(H12:H16) -> 169750.17 | I17: =SUM(I12:I16) -> 172781.67 | J17: =SUM(J12:J16) -> 191337.3 | ... BJ17: =SUM(BJ12:BJ16) -> 925786.27
A19: EBITDA | C19: =C9-C17 -> -78293.549 | D19: =D9-D17 -> -35523.299 | E19: =E9-E17 -> 20773.951 | F19: =F9-F17 -> 33340.576 | G19: =G9-G17 -> 78421.576 | H19: =H9-H17 -> 82659.326 | I19: =I9-I17 -> 85753.826 | J19: =J9-J17 -> 73333.201 | ... BJ19: =BJ9-BJ17 -> 800426.53
A20: % of Sales | C20: =+IF(C7>0,C19/C7,"n/a") -> -1.9558718 | D20: =+IF(D7>0,D19/D7,"n/a") -> -0.15436858 | E20: =+IF(E7>0,E19/E7,"n/a") -> 0.043249332 | F20: =+IF(F7>0,F19/F7,"n/a") -> 0.053721835 | G20: =+IF(G7>0,G19/G7,"n/a") -> 0.09552249 | H20: =+IF(H7>0,H19/H7,"n/a") -> 0.098244313 | I20: =+IF(I7>0,I19/I7,"n/a") -> 0.099507216 | J20: =+IF(J7>0,J19/J7,"n/a") -> 0.083122072 | ... BJ20: =+IF(BJ7>0,BJ19/BJ7,"n/a") -> 0.17156507
A22: Depreciation & Amortization | C22: =CapX!G14 -> 50 | D22: =CapX!H14 -> 50 | E22: =CapX!I14 -> 50 | F22: =CapX!J14 -> 66.666667 | G22: =CapX!K14 -> 66.666667 | H22: =CapX!L14 -> 66.666667 | I22: =CapX!M14 -> 66.666667 | J22: =CapX!N14 -> 83.333333 | ... BJ22: =CapX!BN14 -> 816.66667
A24: Net Income Before Taxes | C24: =+C19-C22 -> -78343.549 | D24: =+D19-D22 -> -35573.299 | E24: =+E19-E22 -> 20723.951 | F24: =+F19-F22 -> 33273.91 | G24: =+G19-G22 -> 78354.91 | H24: =+H19-H22 -> 82592.66 | I24: =+I19-I22 -> 85687.16 | J24: =+J19-J22 -> 73249.868 | ... BJ24: =+BJ19-BJ22 -> 799609.86
A26: Income Taxes | B26: =Assumptions!B12 -> 0.34 | C26: =C24*$B$26 -> -26636.807 | D26: =D24*$B$26 -> -12094.922 | E26: =E24*$B$26 -> 7046.1435 | F26: =F24*$B$26 -> 11313.129 | G26: =G24*$B$26 -> 26640.669 | H26: =H24*$B$26 -> 28081.504 | I26: =I24*$B$26 -> 29133.634 | J26: =J24*$B$26 -> 24904.955 | ... BJ26: =BJ24*$B$26 -> 271867.35
A28: Net Income | C28: =+C24-C26 -> -51706.742 | D28: =+D24-D26 -> -23478.377 | E28: =+E24-E26 -> 13677.808 | F28: =+F24-F26 -> 21960.78 | G28: =+G24-G26 -> 51714.24 | H28: =+H24-H26 -> 54511.155 | I28: =+I24-I26 -> 56553.525 | J28: =+J24-J26 -> 48344.913 | ... BJ28: =+BJ24-BJ26 -> 527742.51
A29: % of Sales | C29: =+IF(C7>0,C28/C7,"n/a") -> -1.2916998 | D29: =+IF(D7>0,D28/D7,"n/a") -> -0.10202667 | E29: =+IF(E7>0,E28/E7,"n/a") -> 0.028475856 | F29: =+IF(F7>0,F28/F7,"n/a") -> 0.035385513 | G29: =+IF(G7>0,G28/G7,"n/a") -> 0.062991249 | H29: =+IF(H7>0,H28/H7,"n/a") -> 0.064788951 | I29: =+IF(I7>0,I28/I7,"n/a") -> 0.065623706 | J29: =+IF(J7>0,J28/J7,"n/a") -> 0.054798226 | ... BJ29: =+IF(BJ7>0,BJ28/BJ7,"n/a") -> 0.11311741
A30: Annual Net Income | N30: =SUM(C28:N28) -> 111837.61 | Z30: =SUM(O28:Z28) -> -369464.45 | AL30: =SUM(AA28:AL28) -> -139757.82 | AX30: =SUM(AM28:AX28) -> 1904518.6 | BJ30: =SUM(AY28:BJ28) -> 4125036.6

Sheet Bal Sheet
A1: UrbanWind
A2: Projected Balance Sheets
A3: Assumption Inputs
A5: Note: Must must manually link below "Equity" to investment $ of Preferred Capital Raise from "Equity" worksheet in month of estimated close; Total raised to date
B7: Assumptions (Turns in Days by Year)
B8: 1 | C8: 2 | D8: 3 | E8: 4 | F8: 5 | G8: 44562 | H8: 44593 | I8: 44621 | J8: 44652 | K8: 44682 | L8: 44713 | M8: 44743 | N8: 44774 | O8: 44805 | P8: 44835 | Q8: 44866 | R8: 44896 | S8: 44927 | T8: 44958 | U8: 44986 | V8: 45017 | W8: 45047 | X8: 45078 | Y8: 45108 | Z8: 45139 | AA8: 45170 | AB8: 45200 | AC8: 45231 | AD8: 45261 | AE8: 45292 | AF8: 45323 | AG8: 45352 | AH8: 45383 | AI8: 45413 | AJ8: 45444 | AK8: 45474 | AL8: 45505 | AM8: 45536 | AN8: 45566 | AO8: 45597 | AP8: 45627 | AQ8: 45658 | AR8: 45689 | AS8: 45717 | AT8: 45748 | AU8: 45778 | AV8: 45809 | AW8: 45839 | AX8: 45870 | AY8: 45901 | AZ8: 45931 | BA8: 45962 | BB8: 45992 | BC8: 46023 | BD8: 46054 | BE8: 46082 | BF8: 46113 | BG8: 46143 | BH8: 46174 | BI8: 46204 | BJ8: 46235 | BK8: 46266 | BL8: 46296 | BM8: 46327 | BN8: 46357
A9: Assets
A10: Cash & Equivalents | G10: =Cashflow!G22 -> 155313.26 | H10: =G10+Cashflow!H22 -> 220308.38 | I10: =H10+Cashflow!I22 -> 242844.19 | J10: =I10+Cashflow!J22 -> 107097.89 | K10: =J10+Cashflow!K22 -> 217530.04 | L10: =K10+Cashflow!L22 -> 224722.37 | M10: =L10+Cashflow!M22 -> 260927.06 | N10: =M10+Cashflow!N22 -> 287909.8 | O10: =N10+Cashflow!O22 -> 286781.42 | ... BN10: =BM10+Cashflow!BN22 -> 11983258
A11: Accounts Receivables | B11: =Assumptions!B10 -> 30 | C11: =B11 -> 30 | D11: =C11 -> 30 | E11: =D11 -> 30 | F11: =E11 -> 30 | G11: =IF(B11/(30)>1,'Sales Forecast'!H37,'Sales Forecast'!H37*(B11/30)) -> 40030 | H11: =(('Sales Forecast'!H37+'Sales Forecast'!I37)/2)*('Bal Sheet'!$B$11/30) -> 135075 | I11: =(('Sales Forecast'!I37+'Sales Forecast'!J37)/2)*('Bal Sheet'!$B$11/30) -> 355225 | J11: =(('Sales Forecast'!J37+'Sales Forecast'!K37)/2)*('Bal Sheet'!$B$11/30) -> 550472.5 | K11: =(('Sales Forecast'!K37+'Sales Forecast'!L37)/2)*('Bal Sheet'!$B$11/30) -> 720795 | L11: =(('Sales Forecast'!L37+'Sales Forecast'!M37)/2)*('Bal Sheet'!$B$11/30) -> 831170 | M11: =(('Sales Forecast'!M37+'Sales Forecast'!N37)/2)*('Bal Sheet'!$B$11/30) -> 851575 | N11: =(('Sales Forecast'!N37+'Sales Forecast'!O37)/2)*('Bal Sheet'!$B$11/30) -> 872010 | O11: =(('Sales Forecast'!O37+'Sales Forecast'!P37)/2)*('Bal Sheet'!$B$11/30) -> 892475 | ... R11: =(('Sales Forecast'!R37+'Sales Forecast'!S37)/2)*('Bal Sheet'!$B$11/30) -> 954050 | S11: =(('Sales Forecast'!S37+'Sales Forecast'!T37)/2)*('Bal Sheet'!$C$11/30) -> 994627.5 | T11: =(('Sales Forecast'!T37+'Sales Forecast'!U37)/2)*('Bal Sheet'!$C$11/30) -> 1040220 | U11: =(('Sales Forecast'!U37+'Sales Forecast'!V37)/2)*('Bal Sheet'!$C$11/30) -> 1070827.5 | V11: =(('Sales Forecast'!V37+'Sales Forecast'!W37)/2)*('Bal Sheet'!$C$11/30) -> 1101450 | W11: =(('Sales Forecast'!W37+'Sales Forecast'!X37)/2)*('Bal Sheet'!$C$11/30) -> 1132087.5 | X11: =(('Sales Forecast'!X37+'Sales Forecast'!Y37)/2)*('Bal Sheet'!$C$11/30) -> 1207747.5 | Y11: =(('Sales Forecast'!Y37+'Sales Forecast'!Z37)/2)*('Bal Sheet'!$C$11/30) -> 1283430 | Z11: =(('Sales Forecast'!Z37+'Sales Forecast'!AA37)/2)*('Bal Sheet'!$C$11/30) -> 1314127.5 | ... AD11: =(('Sales Forecast'!AD37+'Sales Forecast'!AE37)/2)*('Bal Sheet'!$C$11/30) -> 1467075 | AE11: =(('Sales Forecast'!AE37+'Sales Forecast'!AF37)/2)*('Bal Sheet'!$D$11/30) -> 1612892.5 | AF11: =(('Sales Forecast'!AF37+'Sales Forecast'!AG37)/2)*('Bal Sheet'!$D$11/30) -> 1773762.5 | AG11: =(('Sales Forecast'!AG37+'Sales Forecast'!AH37)/2)*('Bal Sheet'!$D$11/30) -> 1849655 | AH11: =(('Sales Forecast'!AH37+'Sales Forecast'!AI37)/2)*('Bal Sheet'!$D$11/30) -> 1865555 | AI11: =(('Sales Forecast'!AI37+'Sales Forecast'!AJ37)/2)*('Bal Sheet'!$D$11/30) -> 1866455 | AJ11: =(('Sales Forecast'!AJ37+'Sales Forecast'!AK37)/2)*('Bal Sheet'!$D$11/30) -> 1867355 | AK11: =(('Sales Forecast'!AK37+'Sales Forecast'!AL37)/2)*('Bal Sheet'!$D$11/30) -> 1868255 | AL11: =(('Sales Forecast'!AL37+'Sales Forecast'!AM37)/2)*('Bal Sheet'!$D$11/30) -> 1869155 | ... AP11: =(('Sales Forecast'!AP37+'Sales Forecast'!AQ37)/2)*('Bal Sheet'!$D$11/30) -> 1872755 | AQ11: =(('Sales Forecast'!AQ37+'Sales Forecast'!AR37)/2)*('Bal Sheet'!$E$11/30) -> 1973692.5 | AR11: =(('Sales Forecast'!AR37+'Sales Forecast'!AS37)/2)*('Bal Sheet'!$E$11/30) -> 2164690 | AS11: =(('Sales Forecast'!AS37+'Sales Forecast'!AT37)/2)*('Bal Sheet'!$E$11/30) -> 2350740 | AT11: =(('Sales Forecast'!AT37+'Sales Forecast'!AU37)/2)*('Bal Sheet'!$E$11/30) -> 2541850 | AU11: =(('Sales Forecast'!AU37+'Sales Forecast'!AV37)/2)*('Bal Sheet'!$E$11/30) -> 2703012.5 | AV11: =(('Sales Forecast'!AV37+'Sales Forecast'!AW37)/2)*('Bal Sheet'!$E$11/30) -> 2769197.5 | AW11: =(('Sales Forecast'!AW37+'Sales Forecast'!AX37)/2)*('Bal Sheet'!$E$11/30) -> 2805397.5 | AX11: =(('Sales Forecast'!AX37+'Sales Forecast'!AY37)/2)*('Bal Sheet'!$E$11/30) -> 2841612.5 | ... BB11: =(('Sales Forecast'!BB37+'Sales Forecast'!BC37)/2)*('Bal Sheet'!$E$11/30) -> 2846472.5 | BC11: =(('Sales Forecast'!BC37+'Sales Forecast'!BD37)/2)*('Bal Sheet'!$F$11/30) -> 2897710 | BD11: =(('Sales Forecast'!BD37+'Sales Forecast'!BE37)/2)*('Bal Sheet'!$F$11/30) -> 3044000 | BE11: =(('Sales Forecast'!BE37+'Sales Forecast'!BF37)/2)*('Bal Sheet'!$F$11/30) -> 3175335 | BF11: =(('Sales Forecast'!BF37+'Sales Forecast'!BG37)/2)*('Bal Sheet'!$F$11/30) -> 3306715 | BG11: =(('Sales Forecast'!BG37+'Sales Forecast'!BH37)/2)*('Bal Sheet'!$F$11/30) -> 3453147.5 | BH11: =(('Sales Forecast'!BH37+'Sales Forecast'!BI37)/2)*('Bal Sheet'!$F$11/30) -> 3584625 | BI11: =(('Sales Forecast'!BI37+'Sales Forecast'!BJ37)/2)*('Bal Sheet'!$F$11/30) -> 3716147.5 | BJ11: =(('Sales Forecast'!BJ37+'Sales Forecast'!BK37)/2)*('Bal Sheet'!$F$11/30) -> 3862722.5 | ... BN11: =(('Sales Forecast'!BN37+'Sales Forecast'!BO37)/2)*('Bal Sheet'!$F$11/30) -> 4584532.5
A12: Inventories | G12: =COGS!G21 -> 28021 | H12: =COGS!H21 -> 161084 | I12: =COGS!I21 -> 336231 | J12: =COGS!J21 -> 434430.5 | K12: =COGS!K21 -> 574682.5 | L12: =COGS!L21 -> 588955.5 | M12: =COGS!M21 -> 603249.5 | N12: =COGS!N21 -> 617564.5 | ... BN12: =COGS!BN21 -> 2939227.2
A13: Fixed Assets, net | G13: =CapX!G22-CapX!G14 -> 2950 | H13: =G13+CapX!H22-CapX!H14 -> 2900 | I13: =H13+CapX!I22-CapX!I14 -> 2850 | J13: =I13+CapX!J22-CapX!J14 -> 3783.3333 | K13: =J13+CapX!K22-CapX!K14 -> 3716.6667 | L13: =K13+CapX!L22-CapX!L14 -> 3650 | M13: =L13+CapX!M22-CapX!M14 -> 3583.3333 | N13: =M13+CapX!N22-CapX!N14 -> 4500 | O13: =N13+CapX!O22-CapX!O14 -> 7366.6667 | ... BN13: =BM13+CapX!BN22-CapX!BN14 -> 13408.333
A14: Total Assets | G14: =SUM(G10:G13) -> 226314.26 | H14: =SUM(H10:H13) -> 519367.38 | I14: =SUM(I10:I13) -> 937150.19 | J14: =SUM(J10:J13) -> 1095784.2 | K14: =SUM(K10:K13) -> 1516724.2 | L14: =SUM(L10:L13) -> 1648497.9 | M14: =SUM(M10:M13) -> 1719334.9 | N14: =SUM(N10:N13) -> 1781984.3 | ... BN14: =SUM(BN10:BN13) -> 19520426
A15: Liabilities & Stockholders' Equity
A16: Liabilities
